Workbook

Sheet Class List
A2: NO. | B2: LAST NAME | C2: , | D2: FIRST NAME | E2: MI | G2: PROGRAM
A3: 1 | B3: BACALSO | C3: , | D3: HELEN | E3: S. | F3: =CONCATENATE(B3, ", ", D3, " ", E3) -> BACALSO, HELEN S. | G3: BSED-MATH
A4: 2 | C4: , | F4: =CONCATENATE(B4, ", ", D4, " ", E4) -> ,
A5: 3 | C5: , | F5: =CONCATENATE(B5, ", ", D5, " ", E5) -> ,
A6: 4 | C6: , | F6: =CONCATENATE(B6, ", ", D6, " ", E6) -> , | I6: S.Y./ Semester: | J6: First Semester, A.Y. 2026 - 2027
A7: 5 | C7: , | F7: =CONCATENATE(B7, ", ", D7, " ", E7) -> , | I7: Program: | J7: Department of Business Management & Entrepreneurship
A8: 6 | C8: , | F8: =CONCATENATE(B8, ", ", D8, " ", E8) -> , | I8: Instructor: | J8: MARL VINCENT L. LABITAD, MPA
A9: 7 | C9: , | F9: =CONCATENATE(B9, ", ", D9, " ", E9) -> , | I9: Course No: | J9: ABM 1
A10: 8 | C10: , | F10: =CONCATENATE(B10, ", ", D10, " ", E10) -> , | I10: Descriptive Title: | J10: ORGANZIATION AND MANAGEMENT
A11: 9 | C11: , | F11: =CONCATENATE(B11, ", ", D11, " ", E11) -> , | I11: Schedule: | J11: MONDAY (9:00-10:30 AM) & WED (7:30-9:00 AM)
A12: 10 | C12: , | F12: =CONCATENATE(B12, ", ", D12, " ", E12) -> , | I12: Year and Section: | J12: BSHM 1 - DAISY
A13: 11 | C13: , | F13: =CONCATENATE(B13, ", ", D13, " ", E13) -> ,
A14: 12 | C14: , | F14: =CONCATENATE(B14, ", ", D14, " ", E14) -> ,
A15: 13 | C15: , | F15: =CONCATENATE(B15, ", ", D15, " ", E15) -> , | I15: IMPORTANT NOTES:
A16: 14 | C16: , | F16: =CONCATENATE(B16, ", ", D16, " ", E16) -> ,
A17: 15 | C17: , | F17: =CONCATENATE(B17, ", ", D17, " ", E17) -> , | H17: 1 | I17: Invalid Entries
A18: 16 | C18: , | F18: =CONCATENATE(B18, ", ", D18, " ", E18) -> , | I18: This Electronic Class Record Template will display #REF and will not compute if
A19: 17 | C19: , | F19: =CONCATENATE(B19, ", ", D19, " ", E19) -> , | J19: * the Score and No. of items is blank
A20: 18 | C20: , | F20: =CONCATENATE(B20, ", ", D20, " ", E20) -> , | J20: * the data entered is not a numeric type
A21: 19 | C21: , | F21: =CONCATENATE(B21, ", ", D21, " ", E21) -> , | J21: * some cells are deleted
A22: 20 | C22: , | F22: =CONCATENATE(B22, ", ", D22, " ", E22) -> ,
A23: 21 | C23: , | F23: =CONCATENATE(B23, ", ", D23, " ", E23) -> , | H23: 2 | I23: Security
A24: 22 | C24: , | F24: =CONCATENATE(B24, ", ", D24, " ", E24) -> , | I24: For security reasons, we add protection to the worksheet and other locked cells to prevent erroneous computations
A25: 23 | C25: , | F25: =CONCATENATE(B25, ", ", D25, " ", E25) -> ,
A26: 24 | C26: , | F26: =CONCATENATE(B26, ", ", D26, " ", E26) -> , | H26: 3 | I26: Checked by
A27: 25 | C27: , | F27: =CONCATENATE(B27, ", ", D27, " ", E27) -> , | I27: kindly indicate your immediate head (dean or department chair). In the case of those teaching courses from other departments,
A28: 26 | C28: , | F28: =CONCATENATE(B28, ", ", D28, " ", E28) -> , | I28: indicate the dean or department chair where the course/ subject you are teaching belongs.
A29: 27 | C29: , | F29: =CONCATENATE(B29, ", ", D29, " ", E29) -> ,
A30: 28 | C30: , | F30: =CONCATENATE(B30, ", ", D30, " ", E30) -> , | H30: 4 | I30: Coursework
A31: 29 | C31: , | F31: =CONCATENATE(B31, ", ", D31, " ", E31) -> , | I31: Minimum number of entries per term
A32: 30 | C32: , | F32: =CONCATENATE(B32, ", ", D32, " ", E32) -> , | J32: *Prelim: 4
A33: 31 | C33: , | F33: =CONCATENATE(B33, ", ", D33, " ", E33) -> , | J33: *Midterm: 4
A34: 32 | C34: , | F34: =CONCATENATE(B34, ", ", D34, " ", E34) -> , | J34: *Final: 3
A35: 33 | C35: , | F35: =CONCATENATE(B35, ", ", D35, " ", E35) -> ,
A36: 34 | C36: , | F36: =CONCATENATE(B36, ", ", D36, " ", E36) -> ,
A37: 35 | C37: , | F37: =CONCATENATE(B37, ", ", D37, " ", E37) -> ,
A38: 36 | C38: , | F38: =CONCATENATE(B38, ", ", D38, " ", E38) -> ,
A39: 37 | C39: , | F39: =CONCATENATE(B39, ", ", D39, " ", E39) -> ,
A40: 38 | C40: , | F40: =CONCATENATE(B40, ", ", D40, " ", E40) -> ,
A41: 39 | C41: , | F41: =CONCATENATE(B41, ", ", D41, " ", E41) -> ,
...

Sheet PRELIM
A2: TALISAY CITY COLLEGE
A3: Poblacion, Talisay City, Cebu
A4: ='Class List'!J6 -> First Semester, A.Y. 2026 - 2027
A5: ='Class List'!J7 -> Department of Business Management & Entrepreneurship
A7: Instructor : | E7: ='Class List'!J8 -> MARL VINCENT L. LABITAD, MPA
A8: Course No: | E8: ='Class List'!J9 -> ABM 1
A9: Descriptive Title: | E9: ='Class List'!J10 -> ORGANZIATION AND MANAGEMENT
A10: Schedule: | E10: ='Class List'!J11 -> MONDAY (9:00-10:30 AM) & WED (7:30-9:00 AM)
A12: P r e l i m
A14: NAME | F14: ATTENDANCE (15%) | P14: PARTICIPATION and OTHER COURSEWORK (35%) | Z14: MAJOR PERFORMANCE (25%) | AD14: MAJOR EXAM (25%) | AH14: PRELIM GRADE
F16: A1 | G16: A2 | H16: A3 | I16: A4 | J16: A5 | K16: A6 | L16: TO | M16: %EQ | N16: GE | O16: 0.15 | P16: CW1 | Q16: CW2 | R16: CW3 | S16: CW4 | T16: CW5 | U16: CW6 | V16: TO | W16: %EQ | X16: GE | Y16: 0.35 | Z16: MP | AA16: %EQ | AB16: GE | AC16: 0.25 | AD16: ST | AE16: %EQ | AF16: GE | AG16: 0.25
A17: # | B17: FAMILY NAME | C17: , | D17: FIRST NAME | E17: M.I. | F17: 10 | G17: 10 | H17: 10 | L17: =SUM(F17:K17) -> 30 | M17: =(L17/$L$17)*100 -> 100 | N17: =LOOKUP(M17,{0,1,9,17,25,33,41,49,57,66,75,76,77,78,79,80,81,82,83,84,85,86,87,88,89,90,91,93,95,97,99},{"4.0","3.9","3.8","3.7","3.6","3.5","3.4","3.3","3.2","3.1","3.0","2.9","2.8","2.7","2.6","2.5","2.4","2.3","2.2","2.1","2.0","1.9","1.8","1.7","1.6","1.5","1.4","1.3","1.2","1.1","1.0"}) -> 1.0 | O17: =N17*$O$16 -> 0.15 | P17: 20 | Q17: 20 | V17: =SUM(P17:U17) -> 40 | W17: =(V17/$V$17)*100 -> 100 | X17: =LOOKUP(W17,{0,1,9,17,25,33,41,49,57,66,75,76,77,78,79,80,81,82,83,84,85,86,87,88,89,90,91,93,95,97,99},{"4.0","3.9","3.8","3.7","3.6","3.5","3.4","3.3","3.2","3.1","3.0","2.9","2.8","2.7","2.6","2.5","2.4","2.3","2.2","2.1","2.0","1.9","1.8","1.7","1.6","1.5","1.4","1.3","1.2","1.1","1.0"}) -> 1.0 | Y17: =X17*$Y$16 -> 0.35 | Z17: 100 | AA17: =(Z17/$Z$17)*100 -> 100 | AB17: =LOOKUP(AA17,{0,1,9,17,25,33,41,49,57,66,75,76,77,78,79,80,81,82,83,84,85,86,87,88,89,90,91,93,95,97,99},{"4.0","3.9","3.8","3.7","3.6","3.5","3.4","3.3","3.2","3.1","3.0","2.9","2.8","2.7","2.6","2.5","2.4","2.3","2.2","2.1","2.0","1.9","1.8","1.7","1.6","1.5","1.4","1.3","1.2","1.1","1.0"}) -> 1.0 | AC17: =AB17*$AC$16 -> 0.25 | AD17: 100 | AE17: =(AD17/$AD$17)*100 -> 100 | AF17: =LOOKUP(AE17,{0,1,9,17,25,33,41,49,57,66,75,76,77,78,79,80,81,82,83,84,85,86,87,88,89,90,91,93,95,97,99},{"4.0","3.9","3.8","3.7","3.6","3.5","3.4","3.3","3.2","3.1","3.0","2.9","2.8","2.7","2.6","2.5","2.4","2.3","2.2","2.1","2.0","1.9","1.8","1.7","1.6","1.5","1.4","1.3","1.2","1.1","1.0"}) -> 1.0 | AG17: =AF17*$AG$16 -> 0.25 | AH17: =O17+Y17+AC17+AG17 -> 1
A19: ='Class List'!A3 -> 1 | B19: ='Class List'!B3 -> BACALSO | C19: ='Class List'!C3 -> , | D19: ='Class List'!D3 -> HELEN | E19: ='Class List'!E3 -> S. | L19: =SUM(F19:K19) -> 0 | M19: =(L19/$L$17)*100 -> 0 | N19: =LOOKUP(M19,{0,1,9,17,25,33,41,49,57,66,75,76,77,78,79,80,81,82,83,84,85,86,87,88,89,90,91,93,95,97,99},{"4.0","3.9","3.8","3.7","3.6","3.5","3.4","3.3","3.2","3.1","3.0","2.9","2.8","2.7","2.6","2.5","2.4","2.3","2.2","2.1","2.0","1.9","1.8","1.7","1.6","1.5","1.4","1.3","1.2","1.1","1.0"}) -> 4.0 | O19: =N19*$O$16 -> 0.6 | V19: =SUM(P19:U19) -> 0 | W19: =(V19/$V$17)*100 -> 0 | X19: =LOOKUP(W19,{0,1,9,17,25,33,41,49,57,66,75,76,77,78,79,80,81,82,83,84,85,86,87,88,89,90,91,93,95,97,99},{"4.0","3.9","3.8","3.7","3.6","3.5","3.4","3.3","3.2","3.1","3.0","2.9","2.8","2.7","2.6","2.5","2.4","2.3","2.2","2.1","2.0","1.9","1.8","1.7","1.6","1.5","1.4","1.3","1.2","1.1","1.0"}) -> 4.0 | Y19: =X19*$Y$16 -> 1.4 | AA19: =(Z19/$Z$17)*100 -> 0 | AB19: =LOOKUP(AA19,{0,1,9,17,25,33,41,49,57,66,75,76,77,78,79,80,81,82,83,84,85,86,87,88,89,90,91,93,95,97,99},{"4.0","3.9","3.8","3.7","3.6","3.5","3.4","3.3","3.2","3.1","3.0","2.9","2.8","2.7","2.6","2.5","2.4","2.3","2.2","2.1","2.0","1.9","1.8","1.7","1.6","1.5","1.4","1.3","1.2","1.1","1.0"}) -> 4.0 | AC19: =AB19*$AC$16 -> 1 | AE19: =(AD19/$AD$17)*100 -> 0 | AF19: =LOOKUP(AE19,{0,1,9,17,25,33,41,49,57,66,75,76,77,78,79,80,81,82,83,84,85,86,87,88,89,90,91,93,95,97,99},{"4.0","3.9","3.8","3.7","3.6","3.5","3.4","3.3","3.2","3.1","3.0","2.9","2.8","2.7","2.6","2.5","2.4","2.3","2.2","2.1","2.0","1.9","1.8","1.7","1.6","1.5","1.4","1.3","1.2","1.1","1.0"}) -> 4.0 | AG19: =AF19*$AG$16 -> 1 | AH19: =O19+Y19+AC19+AG19 -> 4
A20: ='Class List'!A4 -> 2 | B20: ='Class List'!B4 -> 0 | C20: ='Class List'!C4 -> , | D20: ='Class List'!D4 -> 0 | E20: ='Class List'!E4 -> 0 | L20: =SUM(F20:K20) -> 0 | M20: =(L20/$L$17)*100 -> 0 | N20: =LOOKUP(M20,{0,1,9,17,25,33,41,49,57,66,75,76,77,78,79,80,81,82,83,84,85,86,87,88,89,90,91,93,95,97,99},{"4.0","3.9","3.8","3.7","3.6","3.5","3.4","3.3","3.2","3.1","3.0","2.9","2.8","2.7","2.6","2.5","2.4","2.3","2.2","2.1","2.0","1.9","1.8","1.7","1.6","1.5","1.4","1.3","1.2","1.1","1.0"}) -> 4.0 | O20: =N20*$O$16 -> 0.6 | V20: =SUM(P20:U20) -> 0 | W20: =(V20/$V$17)*100 -> 0 | X20: =LOOKUP(W20,{0,1,9,17,25,33,41,49,57,66,75,76,77,78,79,80,81,82,83,84,85,86,87,88,89,90,91,93,95,97,99},{"4.0","3.9","3.8","3.7","3.6","3.5","3.4","3.3","3.2","3.1","3.0","2.9","2.8","2.7","2.6","2.5","2.4","2.3","2.2","2.1","2.0","1.9","1.8","1.7","1.6","1.5","1.4","1.3","1.2","1.1","1.0"}) -> 4.0 | Y20: =X20*$Y$16 -> 1.4 | AA20: =(Z20/$Z$17)*100 -> 0 | AB20: =LOOKUP(AA20,{0,1,9,17,25,33,41,49,57,66,75,76,77,78,79,80,81,82,83,84,85,86,87,88,89,90,91,93,95,97,99},{"4.0","3.9","3.8","3.7","3.6","3.5","3.4","3.3","3.2","3.1","3.0","2.9","2.8","2.7","2.6","2.5","2.4","2.3","2.2","2.1","2.0","1.9","1.8","1.7","1.6","1.5","1.4","1.3","1.2","1.1","1.0"}) -> 4.0 | AC20: =AB20*$AC$16 -> 1 | AE20: =(AD20/$AD$17)*100 -> 0 | AF20: =LOOKUP(AE20,{0,1,9,17,25,33,41,49,57,66,75,76,77,78,79,80,81,82,83,84,85,86,87,88,89,90,91,93,95,97,99},{"4.0","3.9","3.8","3.7","3.6","3.5","3.4","3.3","3.2","3.1","3.0","2.9","2.8","2.7","2.6","2.5","2.4","2.3","2.2","2.1","2.0","1.9","1.8","1.7","1.6","1.5","1.4","1.3","1.2","1.1","1.0"}) -> 4.0 | AG20: =AF20*$AG$16 -> 1 | AH20: =O20+Y20+AC20+AG20 -> 4
A21: ='Class List'!A5 -> 3 | B21: ='Class List'!B5 -> 0 | C21: ='Class List'!C5 -> , | D21: ='Class List'!D5 -> 0 | E21: ='Class List'!E5 -> 0 | L21: =SUM(F21:K21) -> 0 | M21: =(L21/$L$17)*100 -> 0 | N21: =LOOKUP(M21,{0,1,9,17,25,33,41,49,57,66,75,76,77,78,79,80,81,82,83,84,85,86,87,88,89,90,91,93,95,97,99},{"4.0","3.9","3.8","3.7","3.6","3.5","3.4","3.3","3.2","3.1","3.0","2.9","2.8","2.7","2.6","2.5","2.4","2.3","2.2","2.1","2.0","1.9","1.8","1.7","1.6","1.5","1.4","1.3","1.2","1.1","1.0"}) -> 4.0 | O21: =N21*$O$16 -> 0.6 | V21: =SUM(P21:U21) -> 0 | W21: =(V21/$V$17)*100 -> 0 | X21: =LOOKUP(W21,{0,1,9,17,25,33,41,49,57,66,75,76,77,78,79,80,81,82,83,84,85,86,87,88,89,90,91,93,95,97,99},{"4.0","3.9","3.8","3.7","3.6","3.5","3.4","3.3","3.2","3.1","3.0","2.9","2.8","2.7","2.6","2.5","2.4","2.3","2.2","2.1","2.0","1.9","1.8","1.7","1.6","1.5","1.4","1.3","1.2","1.1","1.0"}) -> 4.0 | Y21: =X21*$Y$16 -> 1.4 | AA21: =(Z21/$Z$17)*100 -> 0 | AB21: =LOOKUP(AA21,{0,1,9,17,25,33,41,49,57,66,75,76,77,78,79,80,81,82,83,84,85,86,87,88,89,90,91,93,95,97,99},{"4.0","3.9","3.8","3.7","3.6","3.5","3.4","3.3","3.2","3.1","3.0","2.9","2.8","2.7","2.6","2.5","2.4","2.3","2.2","2.1","2.0","1.9","1.8","1.7","1.6","1.5","1.4","1.3","1.2","1.1","1.0"}) -> 4.0 | AC21: =AB21*$AC$16 -> 1 | AE21: =(AD21/$AD$17)*100 -> 0 | AF21: =LOOKUP(AE21,{0,1,9,17,25,33,41,49,57,66,75,76,77,78,79,80,81,82,83,84,85,86,87,88,89,90,91,93,95,97,99},{"4.0","3.9","3.8","3.7","3.6","3.5","3.4","3.3","3.2","3.1","3.0","2.9","2.8","2.7","2.6","2.5","2.4","2.3","2.2","2.1","2.0","1.9","1.8","1.7","1.6","1.5","1.4","1.3","1.2","1.1","1.0"}) -> 4.0 | AG21: =AF21*$AG$16 -> 1 | AH21: =O21+Y21+AC21+AG21 -> 4
A22: ='Class List'!A6 -> 4 | B22: ='Class List'!B6 -> 0 | C22: ='Class List'!C6 -> , | D22: ='Class List'!D6 -> 0 | E22: ='Class List'!E6 -> 0 | L22: =SUM(F22:K22) -> 0 | M22: =(L22/$L$17)*100 -> 0 | N22: =LOOKUP(M22,{0,1,9,17,25,33,41,49,57,66,75,76,77,78,79,80,81,82,83,84,85,86,87,88,89,90,91,93,95,97,99},{"4.0","3.9","3.8","3.7","3.6","3.5","3.4","3.3","3.2","3.1","3.0","2.9","2.8","2.7","2.6","2.5","2.4","2.3","2.2","2.1","2.0","1.9","1.8","1.7","1.6","1.5","1.4","1.3","1.2","1.1","1.0"}) -> 4.0 | O22: =N22*$O$16 -> 0.6 | V22: =SUM(P22:U22) -> 0 | W22: =(V22/$V$17)*100 -> 0 | X22: =LOOKUP(W22,{0,1,9,17,25,33,41,49,57,66,75,76,77,78,79,80,81,82,83,84,85,86,87,88,89,90,91,93,95,97,99},{"4.0","3.9","3.8","3.7","3.6","3.5","3.4","3.3","3.2","3.1","3.0","2.9","2.8","2.7","2.6","2.5","2.4","2.3","2.2","2.1","2.0","1.9","1.8","1.7","1.6","1.5","1.4","1.3","1.2","1.1","1.0"}) -> 4.0 | Y22: =X22*$Y$16 -> 1.4 | AA22: =(Z22/$Z$17)*100 -> 0 | AB22: =LOOKUP(AA22,{0,1,9,17,25,33,41,49,57,66,75,76,77,78,79,80,81,82,83,84,85,86,87,88,89,90,91,93,95,97,99},{"4.0","3.9","3.8","3.7","3.6","3.5","3.4","3.3","3.2","3.1","3.0","2.9","2.8","2.7","2.6","2.5","2.4","2.3","2.2","2.1","2.0","1.9","1.8","1.7","1.6","1.5","1.4","1.3","1.2","1.1","1.0"}) -> 4.0 | AC22: =AB22*$AC$16 -> 1 | AE22: =(AD22/$AD$17)*100 -> 0 | AF22: =LOOKUP(AE22,{0,1,9,17,25,33,41,49,57,66,75,76,77,78,79,80,81,82,83,84,85,86,87,88,89,90,91,93,95,97,99},{"4.0","3.9","3.8","3.7","3.6","3.5","3.4","3.3","3.2","3.1","3.0","2.9","2.8","2.7","2.6","2.5","2.4","2.3","2.2","2.1","2.0","1.9","1.8","1.7","1.6","1.5","1.4","1.3","1.2","1.1","1.0"}) -> 4.0 | AG22: =AF22*$AG$16 -> 1 | AH22: =O22+Y22+AC22+AG22 -> 4
A23: ='Class List'!A7 -> 5 | B23: ='Class List'!B7 -> 0 | C23: ='Class List'!C7 -> , | D23: ='Class List'!D7 -> 0 | E23: ='Class List'!E7 -> 0 | L23: =SUM(F23:K23) -> 0 | M23: =(L23/$L$17)*100 -> 0 | N23: =LOOKUP(M23,{0,1,9,17,25,33,41,49,57,66,75,76,77,78,79,80,81,82,83,84,85,86,87,88,89,90,91,93,95,97,99},{"4.0","3.9","3.8","3.7","3.6","3.5","3.4","3.3","3.2","3.1","3.0","2.9","2.8","2.7","2.6","2.5","2.4","2.3","2.2","2.1","2.0","1.9","1.8","1.7","1.6","1.5","1.4","1.3","1.2","1.1","1.0"}) -> 4.0 | O23: =N23*$O$16 -> 0.6 | V23: =SUM(P23:U23) -> 0 | W23: =(V23/$V$17)*100 -> 0 | X23: =LOOKUP(W23,{0,1,9,17,25,33,41,49,57,66,75,76,77,78,79,80,81,82,83,84,85,86,87,88,89,90,91,93,95,97,99},{"4.0","3.9","3.8","3.7","3.6","3.5","3.4","3.3","3.2","3.1","3.0","2.9","2.8","2.7","2.6","2.5","2.4","2.3","2.2","2.1","2.0","1.9","1.8","1.7","1.6","1.5","1.4","1.3","1.2","1.1","1.0"}) -> 4.0 | Y23: =X23*$Y$16 -> 1.4 | AA23: =(Z23/$Z$17)*100 -> 0 | AB23: =LOOKUP(AA23,{0,1,9,17,25,33,41,49,57,66,75,76,77,78,79,80,81,82,83,84,85,86,87,88,89,90,91,93,95,97,99},{"4.0","3.9","3.8","3.7","3.6","3.5","3.4","3.3","3.2","3.1","3.0","2.9","2.8","2.7","2.6","2.5","2.4","2.3","2.2","2.1","2.0","1.9","1.8","1.7","1.6","1.5","1.4","1.3","1.2","1.1","1.0"}) -> 4.0 | AC23: =AB23*$AC$16 -> 1 | AE23: =(AD23/$AD$17)*100 -> 0 | AF23: =LOOKUP(AE23,{0,1,9,17,25,33,41,49,57,66,75,76,77,78,79,80,81,82,83,84,85,86,87,88,89,90,91,93,95,97,99},{"4.0","3.9","3.8","3.7","3.6","3.5","3.4","3.3","3.2","3.1","3.0","2.9","2.8","2.7","2.6","2.5","2.4","2.3","2.2","2.1","2.0","1.9","1.8","1.7","1.6","1.5","1.4","1.3","1.2","1.1","1.0"}) -> 4.0 | AG23: =AF23*$AG$16 -> 1 | AH23: =O23+Y23+AC23+AG23 -> 4
A24: ='Class List'!A8 -> 6 | B24: ='Class List'!B8 -> 0 | C24: ='Class List'!C8 -> , | D24: ='Class List'!D8 -> 0 | E24: ='Class List'!E8 -> 0 | L24: =SUM(F24:K24) -> 0 | M24: =(L24/$L$17)*100 -> 0 | N24: =LOOKUP(M24,{0,1,9,17,25,33,41,49,57,66,75,76,77,78,79,80,81,82,83,84,85,86,87,88,89,90,91,93,95,97,99},{"4.0","3.9","3.8","3.7","3.6","3.5","3.4","3.3","3.2","3.1","3.0","2.9","2.8","2.7","2.6","2.5","2.4","2.3","2.2","2.1","2.0","1.9","1.8","1.7","1.6","1.5","1.4","1.3","1.2","1.1","1.0"}) -> 4.0 | O24: =N24*$O$16 -> 0.6 | V24: =SUM(P24:U24) -> 0 | W24: =(V24/$V$17)*100 -> 0 | X24: =LOOKUP(W24,{0,1,9,17,25,33,41,49,57,66,75,76,77,78,79,80,81,82,83,84,85,86,87,88,89,90,91,93,95,97,99},{"4.0","3.9","3.8","3.7","3.6","3.5","3.4","3.3","3.2","3.1","3.0","2.9","2.8","2.7","2.6","2.5","2.4","2.3","2.2","2.1","2.0","1.9","1.8","1.7","1.6","1.5","1.4","1.3","1.2","1.1","1.0"}) -> 4.0 | Y24: =X24*$Y$16 -> 1.4 | AA24: =(Z24/$Z$17)*100 -> 0 | AB24: =LOOKUP(AA24,{0,1,9,17,25,33,41,49,57,66,75,76,77,78,79,80,81,82,83,84,85,86,87,88,89,90,91,93,95,97,99},{"4.0","3.9","3.8","3.7","3.6","3.5","3.4","3.3","3.2","3.1","3.0","2.9","2.8","2.7","2.6","2.5","2.4","2.3","2.2","2.1","2.0","1.9","1.8","1.7","1.6","1.5","1.4","1.3","1.2","1.1","1.0"}) -> 4.0 | AC24: =AB24*$AC$16 -> 1 | AE24: =(AD24/$AD$17)*100 -> 0 | AF24: =LOOKUP(AE24,{0,1,9,17,25,33,41,49,57,66,75,76,77,78,79,80,81,82,83,84,85,86,87,88,89,90,91,93,95,97,99},{"4.0","3.9","3.8","3.7","3.6","3.5","3.4","3.3","3.2","3.1","3.0","2.9","2.8","2.7","2.6","2.5","2.4","2.3","2.2","2.1","2.0","1.9","1.8","1.7","1.6","1.5","1.4","1.3","1.2","1.1","1.0"}) -> 4.0 | AG24: =AF24*$AG$16 -> 1 | AH24: =O24+Y24+AC24+AG24 -> 4
A25: ='Class List'!A9 -> 7 | B25: ='Class List'!B9 -> 0 | C25: ='Class List'!C9 -> , | D25: ='Class List'!D9 -> 0 | E25: ='Class List'!E9 -> 0 | L25: =SUM(F25:K25) -> 0 | M25: =(L25/$L$17)*100 -> 0 | N25: =LOOKUP(M25,{0,1,9,17,25,33,41,49,57,66,75,76,77,78,79,80,81,82,83,84,85,86,87,88,89,90,91,93,95,97,99},{"4.0","3.9","3.8","3.7","3.6","3.5","3.4","3.3","3.2","3.1","3.0","2.9","2.8","2.7","2.6","2.5","2.4","2.3","2.2","2.1","2.0","1.9","1.8","1.7","1.6","1.5","1.4","1.3","1.2","1.1","1.0"}) -> 4.0 | O25: =N25*$O$16 -> 0.6 | V25: =SUM(P25:U25) -> 0 | W25: =(V25/$V$17)*100 -> 0 | X25: =LOOKUP(W25,{0,1,9,17,25,33,41,49,57,66,75,76,77,78,79,80,81,82,83,84,85,86,87,88,89,90,91,93,95,97,99},{"4.0","3.9","3.8","3.7","3.6","3.5","3.4","3.3","3.2","3.1","3.0","2.9","2.8","2.7","2.6","2.5","2.4","2.3","2.2","2.1","2.0","1.9","1.8","1.7","1.6","1.5","1.4","1.3","1.2","1.1","1.0"}) -> 4.0 | Y25: =X25*$Y$16 -> 1.4 | AA25: =(Z25/$Z$17)*100 -> 0 | AB25: =LOOKUP(AA25,{0,1,9,17,25,33,41,49,57,66,75,76,77,78,79,80,81,82,83,84,85,86,87,88,89,90,91,93,95,97,99},{"4.0","3.9","3.8","3.7","3.6","3.5","3.4","3.3","3.2","3.1","3.0","2.9","2.8","2.7","2.6","2.5","2.4","2.3","2.2","2.1","2.0","1.9","1.8","1.7","1.6","1.5","1.4","1.3","1.2","1.1","1.0"}) -> 4.0 | AC25: =AB25*$AC$16 -> 1 | AE25: =(AD25/$AD$17)*100 -> 0 | AF25: =LOOKUP(AE25,{0,1,9,17,25,33,41,49,57,66,75,76,77,78,79,80,81,82,83,84,85,86,87,88,89,90,91,93,95,97,99},{"4.0","3.9","3.8","3.7","3.6","3.5","3.4","3.3","3.2","3.1","3.0","2.9","2.8","2.7","2.6","2.5","2.4","2.3","2.2","2.1","2.0","1.9","1.8","1.7","1.6","1.5","1.4","1.3","1.2","1.1","1.0"}) -> 4.0 | AG25: =AF25*$AG$16 -> 1 | AH25: =O25+Y25+AC25+AG25 -> 4
A26: ='Class List'!A10 -> 8 | B26: ='Class List'!B10 -> 0 | C26: ='Class List'!C10 -> , | D26: ='Class List'!D10 -> 0 | E26: ='Class List'!E10 -> 0 | L26: =SUM(F26:K26) -> 0 | M26: =(L26/$L$17)*100 -> 0 | N26: =LOOKUP(M26,{0,1,9,17,25,33,41,49,57,66,75,76,77,78,79,80,81,82,83,84,85,86,87,88,89,90,91,93,95,97,99},{"4.0","3.9","3.8","3.7","3.6","3.5","3.4","3.3","3.2","3.1","3.0","2.9","2.8","2.7","2.6","2.5","2.4","2.3","2.2","2.1","2.0","1.9","1.8","1.7","1.6","1.5","1.4","1.3","1.2","1.1","1.0"}) -> 4.0 | O26: =N26*$O$16 -> 0.6 | V26: =SUM(P26:U26) -> 0 | W26: =(V26/$V$17)*100 -> 0 | X26: =LOOKUP(W26,{0,1,9,17,25,33,41,49,57,66,75,76,77,78,79,80,81,82,83,84,85,86,87,88,89,90,91,93,95,97,99},{"4.0","3.9","3.8","3.7","3.6","3.5","3.4","3.3","3.2","3.1","3.0","2.9","2.8","2.7","2.6","2.5","2.4","2.3","2.2","2.1","2.0","1.9","1.8","1.7","1.6","1.5","1.4","1.3","1.2","1.1","1.0"}) -> 4.0 | Y26: =X26*$Y$16 -> 1.4 | AA26: =(Z26/$Z$17)*100 -> 0 | AB26: =LOOKUP(AA26,{0,1,9,17,25,33,41,49,57,66,75,76,77,78,79,80,81,82,83,84,85,86,87,88,89,90,91,93,95,97,99},{"4.0","3.9","3.8","3.7","3.6","3.5","3.4","3.3","3.2","3.1","3.0","2.9","2.8","2.7","2.6","2.5","2.4","2.3","2.2","2.1","2.0","1.9","1.8","1.7","1.6","1.5","1.4","1.3","1.2","1.1","1.0"}) -> 4.0 | AC26: =AB26*$AC$16 -> 1 | AE26: =(AD26/$AD$17)*100 -> 0 | AF26: =LOOKUP(AE26,{0,1,9,17,25,33,41,49,57,66,75,76,77,78,79,80,81,82,83,84,85,86,87,88,89,90,91,93,95,97,99},{"4.0","3.9","3.8","3.7","3.6","3.5","3.4","3.3","3.2","3.1","3.0","2.9","2.8","2.7","2.6","2.5","2.4","2.3","2.2","2.1","2.0","1.9","1.8","1.7","1.6","1.5","1.4","1.3","1.2","1.1","1.0"}) -> 4.0 | AG26: =AF26*$AG$16 -> 1 | AH26: =O26+Y26+AC26+AG26 -> 4
A27: ='Class List'!A11 -> 9 | B27: ='Class List'!B11 -> 0 | C27: ='Class List'!C11 -> , | D27: ='Class List'!D11 -> 0 | E27: ='Class List'!E11 -> 0 | L27: =SUM(F27:K27) -> 0 | M27: =(L27/$L$17)*100 -> 0 | N27: =LOOKUP(M27,{0,1,9,17,25,33,41,49,57,66,75,76,77,78,79,80,81,82,83,84,85,86,87,88,89,90,91,93,95,97,99},{"4.0","3.9","3.8","3.7","3.6","3.5","3.4","3.3","3.2","3.1","3.0","2.9","2.8","2.7","2.6","2.5","2.4","2.3","2.2","2.1","2.0","1.9","1.8","1.7","1.6","1.5","1.4","1.3","1.2","1.1","1.0"}) -> 4.0 | O27: =N27*$O$16 -> 0.6 | V27: =SUM(P27:U27) -> 0 | W27: =(V27/$V$17)*100 -> 0 | X27: =LOOKUP(W27,{0,1,9,17,25,33,41,49,57,66,75,76,77,78,79,80,81,82,83,84,85,86,87,88,89,90,91,93,95,97,99},{"4.0","3.9","3.8","3.7","3.6","3.5","3.4","3.3","3.2","3.1","3.0","2.9","2.8","2.7","2.6","2.5","2.4","2.3","2.2","2.1","2.0","1.9","1.8","1.7","1.6","1.5","1.4","1.3","1.2","1.1","1.0"}) -> 4.0 | Y27: =X27*$Y$16 -> 1.4 | AA27: =(Z27/$Z$17)*100 -> 0 | AB27: =LOOKUP(AA27,{0,1,9,17,25,33,41,49,57,66,75,76,77,78,79,80,81,82,83,84,85,86,87,88,89,90,91,93,95,97,99},{"4.0","3.9","3.8","3.7","3.6","3.5","3.4","3.3","3.2","3.1","3.0","2.9","2.8","2.7","2.6","2.5","2.4","2.3","2.2","2.1","2.0","1.9","1.8","1.7","1.6","1.5","1.4","1.3","1.2","1.1","1.0"}) -> 4.0 | AC27: =AB27*$AC$16 -> 1 | AE27: =(AD27/$AD$17)*100 -> 0 | AF27: =LOOKUP(AE27,{0,1,9,17,25,33,41,49,57,66,75,76,77,78,79,80,81,82,83,84,85,86,87,88,89,90,91,93,95,97,99},{"4.0","3.9","3.8","3.7","3.6","3.5","3.4","3.3","3.2","3.1","3.0","2.9","2.8","2.7","2.6","2.5","2.4","2.3","2.2","2.1","2.0","1.9","1.8","1.7","1.6","1.5","1.4","1.3","1.2","1.1","1.0"}) -> 4.0 | AG27: =AF27*$AG$16 -> 1 | AH27: =O27+Y27+AC27+AG27 -> 4
A28: ='Class List'!A12 -> 10 | B28: ='Class List'!B12 -> 0 | C28: ='Class List'!C12 -> , | D28: ='Class List'!D12 -> 0 | E28: ='Class List'!E12 -> 0 | L28: =SUM(F28:K28) -> 0 | M28: =(L28/$L$17)*100 -> 0 | N28: =LOOKUP(M28,{0,1,9,17,25,33,41,49,57,66,75,76,77,78,79,80,81,82,83,84,85,86,87,88,89,90,91,93,95,97,99},{"4.0","3.9","3.8","3.7","3.6","3.5","3.4","3.3","3.2","3.1","3.0","2.9","2.8","2.7","2.6","2.5","2.4","2.3","2.2","2.1","2.0","1.9","1.8","1.7","1.6","1.5","1.4","1.3","1.2","1.1","1.0"}) -> 4.0 | O28: =N28*$O$16 -> 0.6 | V28: =SUM(P28:U28) -> 0 | W28: =(V28/$V$17)*100 -> 0 | X28: =LOOKUP(W28,{0,1,9,17,25,33,41,49,57,66,75,76,77,78,79,80,81,82,83,84,85,86,87,88,89,90,91,93,95,97,99},{"4.0","3.9","3.8","3.7","3.6","3.5","3.4","3.3","3.2","3.1","3.0","2.9","2.8","2.7","2.6","2.5","2.4","2.3","2.2","2.1","2.0","1.9","1.8","1.7","1.6","1.5","1.4","1.3","1.2","1.1","1.0"}) -> 4.0 | Y28: =X28*$Y$16 -> 1.4 | AA28: =(Z28/$Z$17)*100 -> 0 | AB28: =LOOKUP(AA28,{0,1,9,17,25,33,41,49,57,66,75,76,77,78,79,80,81,82,83,84,85,86,87,88,89,90,91,93,95,97,99},{"4.0","3.9","3.8","3.7","3.6","3.5","3.4","3.3","3.2","3.1","3.0","2.9","2.8","2.7","2.6","2.5","2.4","2.3","2.2","2.1","2.0","1.9","1.8","1.7","1.6","1.5","1.4","1.3","1.2","1.1","1.0"}) -> 4.0 | AC28: =AB28*$AC$16 -> 1 | AE28: =(AD28/$AD$17)*100 -> 0 | AF28: =LOOKUP(AE28,{0,1,9,17,25,33,41,49,57,66,75,76,77,78,79,80,81,82,83,84,85,86,87,88,89,90,91,93,95,97,99},{"4.0","3.9","3.8","3.7","3.6","3.5","3.4","3.3","3.2","3.1","3.0","2.9","2.8","2.7","2.6","2.5","2.4","2.3","2.2","2.1","2.0","1.9","1.8","1.7","1.6","1.5","1.4","1.3","1.2","1.1","1.0"}) -> 4.0 | AG28: =AF28*$AG$16 -> 1 | AH28: =O28+Y28+AC28+AG28 -> 4
A29: ='Class List'!A13 -> 11 | B29: ='Class List'!B13 -> 0 | C29: ='Class List'!C13 -> , | D29: ='Class List'!D13 -> 0 | E29: ='Class List'!E13 -> 0 | L29: =SUM(F29:K29) -> 0 | M29: =(L29/$L$17)*100 -> 0 | N29: =LOOKUP(M29,{0,1,9,17,25,33,41,49,57,66,75,76,77,78,79,80,81,82,83,84,85,86,87,88,89,90,91,93,95,97,99},{"4.0","3.9","3.8","3.7","3.6","3.5","3.4","3.3","3.2","3.1","3.0","2.9","2.8","2.7","2.6","2.5","2.4","2.3","2.2","2.1","2.0","1.9","1.8","1.7","1.6","1.5","1.4","1.3","1.2","1.1","1.0"}) -> 4.0 | O29: =N29*$O$16 -> 0.6 | V29: =SUM(P29:U29) -> 0 | W29: =(V29/$V$17)*100 -> 0 | X29: =LOOKUP(W29,{0,1,9,17,25,33,41,49,57,66,75,76,77,78,79,80,81,82,83,84,85,86,87,88,89,90,91,93,95,97,99},{"4.0","3.9","3.8","3.7","3.6","3.5","3.4","3.3","3.2","3.1","3.0","2.9","2.8","2.7","2.6","2.5","2.4","2.3","2.2","2.1","2.0","1.9","1.8","1.7","1.6","1.5","1.4","1.3","1.2","1.1","1.0"}) -> 4.0 | Y29: =X29*$Y$16 -> 1.4 | AA29: =(Z29/$Z$17)*100 -> 0 | AB29: =LOOKUP(AA29,{0,1,9,17,25,33,41,49,57,66,75,76,77,78,79,80,81,82,83,84,85,86,87,88,89,90,91,93,95,97,99},{"4.0","3.9","3.8","3.7","3.6","3.5","3.4","3.3","3.2","3.1","3.0","2.9","2.8","2.7","2.6","2.5","2.4","2.3","2.2","2.1","2.0","1.9","1.8","1.7","1.6","1.5","1.4","1.3","1.2","1.1","1.0"}) -> 4.0 | AC29: =AB29*$AC$16 -> 1 | AE29: =(AD29/$AD$17)*100 -> 0 | AF29: =LOOKUP(AE29,{0,1,9,17,25,33,41,49,57,66,75,76,77,78,79,80,81,82,83,84,85,86,87,88,89,90,91,93,95,97,99},{"4.0","3.9","3.8","3.7","3.6","3.5","3.4","3.3","3.2","3.1","3.0","2.9","2.8","2.7","2.6","2.5","2.4","2.3","2.2","2.1","2.0","1.9","1.8","1.7","1.6","1.5","1.4","1.3","1.2","1.1","1.0"}) -> 4.0 | AG29: =AF29*$AG$16 -> 1 | AH29: =O29+Y29+AC29+AG29 -> 4
A30: ='Class List'!A14 -> 12 | B30: ='Class List'!B14 -> 0 | C30: ='Class List'!C14 -> , | D30: ='Class List'!D14 -> 0 | E30: ='Class List'!E14 -> 0 | L30: =SUM(F30:K30) -> 0 | M30: =(L30/$L$17)*100 -> 0 | N30: =LOOKUP(M30,{0,1,9,17,25,33,41,49,57,66,75,76,77,78,79,80,81,82,83,84,85,86,87,88,89,90,91,93,95,97,99},{"4.0","3.9","3.8","3.7","3.6","3.5","3.4","3.3","3.2","3.1","3.0","2.9","2.8","2.7","2.6","2.5","2.4","2.3","2.2","2.1","2.0","1.9","1.8","1.7","1.6","1.5","1.4","1.3","1.2","1.1","1.0"}) -> 4.0 | O30: =N30*$O$16 -> 0.6 | V30: =SUM(P30:U30) -> 0 | W30: =(V30/$V$17)*100 -> 0 | X30: =LOOKUP(W30,{0,1,9,17,25,33,41,49,57,66,75,76,77,78,79,80,81,82,83,84,85,86,87,88,89,90,91,93,95,97,99},{"4.0","3.9","3.8","3.7","3.6","3.5","3.4","3.3","3.2","3.1","3.0","2.9","2.8","2.7","2.6","2.5","2.4","2.3","2.2","2.1","2.0","1.9","1.8","1.7","1.6","1.5","1.4","1.3","1.2","1.1","1.0"}) -> 4.0 | Y30: =X30*$Y$16 -> 1.4 | AA30: =(Z30/$Z$17)*100 -> 0 | AB30: =LOOKUP(AA30,{0,1,9,17,25,33,41,49,57,66,75,76,77,78,79,80,81,82,83,84,85,86,87,88,89,90,91,93,95,97,99},{"4.0","3.9","3.8","3.7","3.6","3.5","3.4","3.3","3.2","3.1","3.0","2.9","2.8","2.7","2.6","2.5","2.4","2.3","2.2","2.1","2.0","1.9","1.8","1.7","1.6","1.5","1.4","1.3","1.2","1.1","1.0"}) -> 4.0 | AC30: =AB30*$AC$16 -> 1 | AE30: =(AD30/$AD$17)*100 -> 0 | AF30: =LOOKUP(AE30,{0,1,9,17,25,33,41,49,57,66,75,76,77,78,79,80,81,82,83,84,85,86,87,88,89,90,91,93,95,97,99},{"4.0","3.9","3.8","3.7","3.6","3.5","3.4","3.3","3.2","3.1","3.0","2.9","2.8","2.7","2.6","2.5","2.4","2.3","2.2","2.1","2.0","1.9","1.8","1.7","1.6","1.5","1.4","1.3","1.2","1.1","1.0"}) -> 4.0 | AG30: =AF30*$AG$16 -> 1 | AH30: =O30+Y30+AC30+AG30 -> 4
... A78: ='Class List'!A62 -> 60 | B78: ='Class List'!B62 -> 0 | C78: ='Class List'!C62 -> , | D78: ='Class List'!D62 -> 0 | E78: ='Class List'!E62 -> 0 | L78: =SUM(F78:K78) -> 0 | M78: =(L78/$L$17)*100 -> 0 | N78: =LOOKUP(M78,{0,1,9,17,25,33,41,49,57,66,75,76,77,78,79,80,81,82,83,84,85,86,87,88,89,90,91,93,95,97,99},{"4.0","3.9","3.8","3.7","3.6","3.5","3.4","3.3","3.2","3.1","3.0","2.9","2.8","2.7","2.6","2.5","2.4","2.3","2.2","2.1","2.0","1.9","1.8","1.7","1.6","1.5","1.4","1.3","1.2","1.1","1.0"}) -> 4.0 | O78: =N78*$O$16 -> 0.6 | V78: =SUM(P78:U78) -> 0 | W78: =(V78/$V$17)*100 -> 0 | X78: =LOOKUP(W78,{0,1,9,17,25,33,41,49,57,66,75,76,77,78,79,80,81,82,83,84,85,86,87,88,89,90,91,93,95,97,99},{"4.0","3.9","3.8","3.7","3.6","3.5","3.4","3.3","3.2","3.1","3.0","2.9","2.8","2.7","2.6","2.5","2.4","2.3","2.2","2.1","2.0","1.9","1.8","1.7","1.6","1.5","1.4","1.3","1.2","1.1","1.0"}) -> 4.0 | Y78: =X78*$Y$16 -> 1.4 | AA78: =(Z78/$Z$17)*100 -> 0 | AB78: =LOOKUP(AA78,{0,1,9,17,25,33,41,49,57,66,75,76,77,78,79,80,81,82,83,84,85,86,87,88,89,90,91,93,95,97,99},{"4.0","3.9","3.8","3.7","3.6","3.5","3.4","3.3","3.2","3.1","3.0","2.9","2.8","2.7","2.6","2.5","2.4","2.3","2.2","2.1","2.0","1.9","1.8","1.7","1.6","1.5","1.4","1.3","1.2","1.1","1.0"}) -> 4.0 | AC78: =AB78*$AC$16 -> 1 | AE78: =(AD78/$AD$17)*100 -> 0 | AF78: =LOOKUP(AE78,{0,1,9,17,25,33,41,49,57,66,75,76,77,78,79,80,81,82,83,84,85,86,87,88,89,90,91,93,95,97,99},{"4.0","3.9","3.8","3.7","3.6","3.5","3.4","3.3","3.2","3.1","3.0","2.9","2.8","2.7","2.6","2.5","2.4","2.3","2.2","2.1","2.0","1.9","1.8","1.7","1.6","1.5","1.4","1.3","1.2","1.1","1.0"}) -> 4.0 | AG78: =AF78*$AG$16 -> 1 | AH78: =O78+Y78+AC78+AG78 -> 4
B81: Prepared by: | F81: Checked by: | Z81: Noted by:
B83: ='Class List'!J8 -> MARL VINCENT L. LABITAD, MPA | F83: MARL VINCENT L. LABITAD, MPA | Z83: RICHEL N. BACALTOS, Ed.D
B84: Faculty | F84: Head, Department of Business Management & Entrepreneurship | Z84: College President

Sheet MIDTERM
A2: TALISAY CITY COLLEGE
A3: Poblacion, Talisay City, Cebu
A4: ='Class List'!J6 -> First Semester, A.Y. 2026 - 2027
A5: ='Class List'!J7 -> Department of Business Management & Entrepreneurship
A7: Instructor : | E7: ='Class List'!J8 -> MARL VINCENT L. LABITAD, MPA
A8: Course No: | E8: ='Class List'!J9 -> ABM 1
A9: Descriptive Title: | E9: ='Class List'!J10 -> ORGANZIATION AND MANAGEMENT
A10: Schedule: | E10: ='Class List'!J11 -> MONDAY (9:00-10:30 AM) & WED (7:30-9:00 AM)
A12: M I D T E R M
A14: NAME | F14: ATTENDANCE (15%) | P14: PARTICIPATION and OTHER COURSEWORK (35%) | Z14: MAJOR PERFORMANCE (25%) | AD14: MAJOR EXAM (25%) | AH14: INITIAL MIDTERM GRADE | AI14: 1/2 | AJ14: PRELIM GRADE | AK14: 1/2 | AL14: MIDTERM GRADE
F16: A1 | G16: A2 | H16: A3 | I16: A4 | J16: A5 | K16: A6 | L16: TO | M16: %EQ | N16: GE | O16: 0.15 | P16: CW1 | Q16: CW2 | R16: CW3 | S16: CW4 | T16: CW5 | U16: CW6 | V16: TO | W16: %EQ | X16: GE | Y16: 0.35 | Z16: MP | AA16: %EQ | AB16: GE | AC16: 0.25 | AD16: ST | AE16: %EQ | AF16: GE | AG16: 0.25
A17: # | B17: FAMILY NAME | C17: , | D17: FIRST NAME | E17: M.I. | F17: 10 | G17: 10 | H17: 10 | L17: =SUM(F17:K17) -> 30 | M17: =(L17/$L$17)*100 -> 100 | N17: =LOOKUP(M17,{0,1,9,17,25,33,41,49,57,66,75,76,77,78,79,80,81,82,83,84,85,86,87,88,89,90,91,93,95,97,99},{"4.0","3.9","3.8","3.7","3.6","3.5","3.4","3.3","3.2","3.1","3.0","2.9","2.8","2.7","2.6","2.5","2.4","2.3","2.2","2.1","2.0","1.9","1.8","1.7","1.6","1.5","1.4","1.3","1.2","1.1","1.0"}) -> 1.0 | O17: =N17*$O$16 -> 0.15 | P17: 20 | Q17: 20 | V17: =SUM(P17:U17) -> 40 | W17: =(V17/$V$17)*100 -> 100 | X17: =LOOKUP(W17,{0,1,9,17,25,33,41,49,57,66,75,76,77,78,79,80,81,82,83,84,85,86,87,88,89,90,91,93,95,97,99},{"4.0","3.9","3.8","3.7","3.6","3.5","3.4","3.3","3.2","3.1","3.0","2.9","2.8","2.7","2.6","2.5","2.4","2.3","2.2","2.1","2.0","1.9","1.8","1.7","1.6","1.5","1.4","1.3","1.2","1.1","1.0"}) -> 1.0 | Y17: =X17*$Y$16 -> 0.35 | Z17: 100 | AA17: =(Z17/$Z$17)*100 -> 100 | AB17: =LOOKUP(AA17,{0,1,9,17,25,33,41,49,57,66,75,76,77,78,79,80,81,82,83,84,85,86,87,88,89,90,91,93,95,97,99},{"4.0","3.9","3.8","3.7","3.6","3.5","3.4","3.3","3.2","3.1","3.0","2.9","2.8","2.7","2.6","2.5","2.4","2.3","2.2","2.1","2.0","1.9","1.8","1.7","1.6","1.5","1.4","1.3","1.2","1.1","1.0"}) -> 1.0 | AC17: =AB17*$AC$16 -> 0.25 | AD17: 100 | AE17: =(AD17/$AD$17)*100 -> 100 | AF17: =LOOKUP(AE17,{0,1,9,17,25,33,41,49,57,66,75,76,77,78,79,80,81,82,83,84,85,86,87,88,89,90,91,93,95,97,99},{"4.0","3.9","3.8","3.7","3.6","3.5","3.4","3.3","3.2","3.1","3.0","2.9","2.8","2.7","2.6","2.5","2.4","2.3","2.2","2.1","2.0","1.9","1.8","1.7","1.6","1.5","1.4","1.3","1.2","1.1","1.0"}) -> 1.0 | AG17: =AF17*$AG$16 -> 0.25 | AH17: =AG17+AC17+Y17+O17 -> 1 | AI17: =(AH17*1)/2 -> 0.5 | AJ17: =PRELIM!AH17 -> 1 | AK17: =(AJ17)/2 -> 0.5 | AL17: =SUM(AK17+AI17) -> 1
A19: ='Class List'!A3 -> 1 | B19: ='Class List'!B3 -> BACALSO | C19: ='Class List'!C3 -> , | D19: ='Class List'!D3 -> HELEN | E19: ='Class List'!E3 -> S. | L19: =SUM(F19:K19) -> 0 | M19: =(L19/$L$17)*100 -> 0 | N19: =LOOKUP(M19,{0,1,9,17,25,33,41,49,57,66,75,76,77,78,79,80,81,82,83,84,85,86,87,88,89,90,91,93,95,97,99},{"4.0","3.9","3.8","3.7","3.6","3.5","3.4","3.3","3.2","3.1","3.0","2.9","2.8","2.7","2.6","2.5","2.4","2.3","2.2","2.1","2.0","1.9","1.8","1.7","1.6","1.5","1.4","1.3","1.2","1.1","1.0"}) -> 4.0 | O19: =N19*$O$16 -> 0.6 | V19: =SUM(P19:U19) -> 0 | W19: =(V19/$V$17)*100 -> 0 | X19: =LOOKUP(W19,{0,1,9,17,25,33,41,49,57,66,75,76,77,78,79,80,81,82,83,84,85,86,87,88,89,90,91,93,95,97,99},{"4.0","3.9","3.8","3.7","3.6","3.5","3.4","3.3","3.2","3.1","3.0","2.9","2.8","2.7","2.6","2.5","2.4","2.3","2.2","2.1","2.0","1.9","1.8","1.7","1.6","1.5","1.4","1.3","1.2","1.1","1.0"}) -> 4.0 | Y19: =X19*$Y$16 -> 1.4 | AA19: =(Z19/$Z$17)*100 -> 0 | AB19: =LOOKUP(AA19,{0,1,9,17,25,33,41,49,57,66,75,76,77,78,79,80,81,82,83,84,85,86,87,88,89,90,91,93,95,97,99},{"4.0","3.9","3.8","3.7","3.6","3.5","3.4","3.3","3.2","3.1","3.0","2.9","2.8","2.7","2.6","2.5","2.4","2.3","2.2","2.1","2.0","1.9","1.8","1.7","1.6","1.5","1.4","1.3","1.2","1.1","1.0"}) -> 4.0 | AC19: =AB19*$AC$16 -> 1 | AE19: =(AD19/$AD$17)*100 -> 0 | AF19: =LOOKUP(AE19,{0,1,9,17,25,33,41,49,57,66,75,76,77,78,79,80,81,82,83,84,85,86,87,88,89,90,91,93,95,97,99},{"4.0","3.9","3.8","3.7","3.6","3.5","3.4","3.3","3.2","3.1","3.0","2.9","2.8","2.7","2.6","2.5","2.4","2.3","2.2","2.1","2.0","1.9","1.8","1.7","1.6","1.5","1.4","1.3","1.2","1.1","1.0"}) -> 4.0 | AG19: =AF19*$AG$16 -> 1 | AH19: =AG19+AC19+Y19+O19 -> 4 | AI19: =(AH19*1)/2 -> 2 | AJ19: =PRELIM!AH19 -> 4 | AK19: =(AJ19)/2 -> 2 | AL19: =SUM(AK19+AI19) -> 4
A20: ='Class List'!A4 -> 2 | B20: ='Class List'!B4 -> 0 | C20: ='Class List'!C4 -> , | D20: ='Class List'!D4 -> 0 | E20: ='Class List'!E4 -> 0 | L20: =SUM(F20:K20) -> 0 | M20: =(L20/$L$17)*100 -> 0 | N20: =LOOKUP(M20,{0,1,9,17,25,33,41,49,57,66,75,76,77,78,79,80,81,82,83,84,85,86,87,88,89,90,91,93,95,97,99},{"4.0","3.9","3.8","3.7","3.6","3.5","3.4","3.3","3.2","3.1","3.0","2.9","2.8","2.7","2.6","2.5","2.4","2.3","2.2","2.1","2.0","1.9","1.8","1.7","1.6","1.5","1.4","1.3","1.2","1.1","1.0"}) -> 4.0 | O20: =N20*$O$16 -> 0.6 | V20: =SUM(P20:U20) -> 0 | W20: =(V20/$V$17)*100 -> 0 | X20: =LOOKUP(W20,{0,1,9,17,25,33,41,49,57,66,75,76,77,78,79,80,81,82,83,84,85,86,87,88,89,90,91,93,95,97,99},{"4.0","3.9","3.8","3.7","3.6","3.5","3.4","3.3","3.2","3.1","3.0","2.9","2.8","2.7","2.6","2.5","2.4","2.3","2.2","2.1","2.0","1.9","1.8","1.7","1.6","1.5","1.4","1.3","1.2","1.1","1.0"}) -> 4.0 | Y20: =X20*$Y$16 -> 1.4 | AA20: =(Z20/$Z$17)*100 -> 0 | AB20: =LOOKUP(AA20,{0,1,9,17,25,33,41,49,57,66,75,76,77,78,79,80,81,82,83,84,85,86,87,88,89,90,91,93,95,97,99},{"4.0","3.9","3.8","3.7","3.6","3.5","3.4","3.3","3.2","3.1","3.0","2.9","2.8","2.7","2.6","2.5","2.4","2.3","2.2","2.1","2.0","1.9","1.8","1.7","1.6","1.5","1.4","1.3","1.2","1.1","1.0"}) -> 4.0 | AC20: =AB20*$AC$16 -> 1 | AE20: =(AD20/$AD$17)*100 -> 0 | AF20: =LOOKUP(AE20,{0,1,9,17,25,33,41,49,57,66,75,76,77,78,79,80,81,82,83,84,85,86,87,88,89,90,91,93,95,97,99},{"4.0","3.9","3.8","3.7","3.6","3.5","3.4","3.3","3.2","3.1","3.0","2.9","2.8","2.7","2.6","2.5","2.4","2.3","2.2","2.1","2.0","1.9","1.8","1.7","1.6","1.5","1.4","1.3","1.2","1.1","1.0"}) -> 4.0 | AG20: =AF20*$AG$16 -> 1 | AH20: =AG20+AC20+Y20+O20 -> 4 | AI20: =(AH20*1)/2 -> 2 | AJ20: =PRELIM!AH20 -> 4 | AK20: =(AJ20)/2 -> 2 | AL20: =SUM(AK20+AI20) -> 4
A21: ='Class List'!A5 -> 3 | B21: ='Class List'!B5 -> 0 | C21: ='Class List'!C5 -> , | D21: ='Class List'!D5 -> 0 | E21: ='Class List'!E5 -> 0 | L21: =SUM(F21:K21) -> 0 | M21: =(L21/$L$17)*100 -> 0 | N21: =LOOKUP(M21,{0,1,9,17,25,33,41,49,57,66,75,76,77,78,79,80,81,82,83,84,85,86,87,88,89,90,91,93,95,97,99},{"4.0","3.9","3.8","3.7","3.6","3.5","3.4","3.3","3.2","3.1","3.0","2.9","2.8","2.7","2.6","2.5","2.4","2.3","2.2","2.1","2.0","1.9","1.8","1.7","1.6","1.5","1.4","1.3","1.2","1.1","1.0"}) -> 4.0 | O21: =N21*$O$16 -> 0.6 | V21: =SUM(P21:U21) -> 0 | W21: =(V21/$V$17)*100 -> 0 | X21: =LOOKUP(W21,{0,1,9,17,25,33,41,49,57,66,75,76,77,78,79,80,81,82,83,84,85,86,87,88,89,90,91,93,95,97,99},{"4.0","3.9","3.8","3.7","3.6","3.5","3.4","3.3","3.2","3.1","3.0","2.9","2.8","2.7","2.6","2.5","2.4","2.3","2.2","2.1","2.0","1.9","1.8","1.7","1.6","1.5","1.4","1.3","1.2","1.1","1.0"}) -> 4.0 | Y21: =X21*$Y$16 -> 1.4 | AA21: =(Z21/$Z$17)*100 -> 0 | AB21: =LOOKUP(AA21,{0,1,9,17,25,33,41,49,57,66,75,76,77,78,79,80,81,82,83,84,85,86,87,88,89,90,91,93,95,97,99},{"4.0","3.9","3.8","3.7","3.6","3.5","3.4","3.3","3.2","3.1","3.0","2.9","2.8","2.7","2.6","2.5","2.4","2.3","2.2","2.1","2.0","1.9","1.8","1.7","1.6","1.5","1.4","1.3","1.2","1.1","1.0"}) -> 4.0 | AC21: =AB21*$AC$16 -> 1 | AE21: =(AD21/$AD$17)*100 -> 0 | AF21: =LOOKUP(AE21,{0,1,9,17,25,33,41,49,57,66,75,76,77,78,79,80,81,82,83,84,85,86,87,88,89,90,91,93,95,97,99},{"4.0","3.9","3.8","3.7","3.6","3.5","3.4","3.3","3.2","3.1","3.0","2.9","2.8","2.7","2.6","2.5","2.4","2.3","2.2","2.1","2.0","1.9","1.8","1.7","1.6","1.5","1.4","1.3","1.2","1.1","1.0"}) -> 4.0 | AG21: =AF21*$AG$16 -> 1 | AH21: =AG21+AC21+Y21+O21 -> 4 | AI21: =(AH21*1)/2 -> 2 | AJ21: =PRELIM!AH21 -> 4 | AK21: =(AJ21)/2 -> 2 | AL21: =SUM(AK21+AI21) -> 4
A22: ='Class List'!A6 -> 4 | B22: ='Class List'!B6 -> 0 | C22: ='Class List'!C6 -> , | D22: ='Class List'!D6 -> 0 | E22: ='Class List'!E6 -> 0 | L22: =SUM(F22:K22) -> 0 | M22: =(L22/$L$17)*100 -> 0 | N22: =LOOKUP(M22,{0,1,9,17,25,33,41,49,57,66,75,76,77,78,79,80,81,82,83,84,85,86,87,88,89,90,91,93,95,97,99},{"4.0","3.9","3.8","3.7","3.6","3.5","3.4","3.3","3.2","3.1","3.0","2.9","2.8","2.7","2.6","2.5","2.4","2.3","2.2","2.1","2.0","1.9","1.8","1.7","1.6","1.5","1.4","1.3","1.2","1.1","1.0"}) -> 4.0 | O22: =N22*$O$16 -> 0.6 | V22: =SUM(P22:U22) -> 0 | W22: =(V22/$V$17)*100 -> 0 | X22: =LOOKUP(W22,{0,1,9,17,25,33,41,49,57,66,75,76,77,78,79,80,81,82,83,84,85,86,87,88,89,90,91,93,95,97,99},{"4.0","3.9","3.8","3.7","3.6","3.5","3.4","3.3","3.2","3.1","3.0","2.9","2.8","2.7","2.6","2.5","2.4","2.3","2.2","2.1","2.0","1.9","1.8","1.7","1.6","1.5","1.4","1.3","1.2","1.1","1.0"}) -> 4.0 | Y22: =X22*$Y$16 -> 1.4 | AA22: =(Z22/$Z$17)*100 -> 0 | AB22: =LOOKUP(AA22,{0,1,9,17,25,33,41,49,57,66,75,76,77,78,79,80,81,82,83,84,85,86,87,88,89,90,91,93,95,97,99},{"4.0","3.9","3.8","3.7","3.6","3.5","3.4","3.3","3.2","3.1","3.0","2.9","2.8","2.7","2.6","2.5","2.4","2.3","2.2","2.1","2.0","1.9","1.8","1.7","1.6","1.5","1.4","1.3","1.2","1.1","1.0"}) -> 4.0 | AC22: =AB22*$AC$16 -> 1 | AE22: =(AD22/$AD$17)*100 -> 0 | AF22: =LOOKUP(AE22,{0,1,9,17,25,33,41,49,57,66,75,76,77,78,79,80,81,82,83,84,85,86,87,88,89,90,91,93,95,97,99},{"4.0","3.9","3.8","3.7","3.6","3.5","3.4","3.3","3.2","3.1","3.0","2.9","2.8","2.7","2.6","2.5","2.4","2.3","2.2","2.1","2.0","1.9","1.8","1.7","1.6","1.5","1.4","1.3","1.2","1.1","1.0"}) -> 4.0 | AG22: =AF22*$AG$16 -> 1 | AH22: =AG22+AC22+Y22+O22 -> 4 | AI22: =(AH22*1)/2 -> 2 | AJ22: =PRELIM!AH22 -> 4 | AK22: =(AJ22)/2 -> 2 | AL22: =SUM(AK22+AI22) -> 4
A23: ='Class List'!A7 -> 5 | B23: ='Class List'!B7 -> 0 | C23: ='Class List'!C7 -> , | D23: ='Class List'!D7 -> 0 | E23: ='Class List'!E7 -> 0 | L23: =SUM(F23:K23) -> 0 | M23: =(L23/$L$17)*100 -> 0 | N23: =LOOKUP(M23,{0,1,9,17,25,33,41,49,57,66,75,76,77,78,79,80,81,82,83,84,85,86,87,88,89,90,91,93,95,97,99},{"4.0","3.9","3.8","3.7","3.6","3.5","3.4","3.3","3.2","3.1","3.0","2.9","2.8","2.7","2.6","2.5","2.4","2.3","2.2","2.1","2.0","1.9","1.8","1.7","1.6","1.5","1.4","1.3","1.2","1.1","1.0"}) -> 4.0 | O23: =N23*$O$16 -> 0.6 | V23: =SUM(P23:U23) -> 0 | W23: =(V23/$V$17)*100 -> 0 | X23: =LOOKUP(W23,{0,1,9,17,25,33,41,49,57,66,75,76,77,78,79,80,81,82,83,84,85,86,87,88,89,90,91,93,95,97,99},{"4.0","3.9","3.8","3.7","3.6","3.5","3.4","3.3","3.2","3.1","3.0","2.9","2.8","2.7","2.6","2.5","2.4","2.3","2.2","2.1","2.0","1.9","1.8","1.7","1.6","1.5","1.4","1.3","1.2","1.1","1.0"}) -> 4.0 | Y23: =X23*$Y$16 -> 1.4 | AA23: =(Z23/$Z$17)*100 -> 0 | AB23: =LOOKUP(AA23,{0,1,9,17,25,33,41,49,57,66,75,76,77,78,79,80,81,82,83,84,85,86,87,88,89,90,91,93,95,97,99},{"4.0","3.9","3.8","3.7","3.6","3.5","3.4","3.3","3.2","3.1","3.0","2.9","2.8","2.7","2.6","2.5","2.4","2.3","2.2","2.1","2.0","1.9","1.8","1.7","1.6","1.5","1.4","1.3","1.2","1.1","1.0"}) -> 4.0 | AC23: =AB23*$AC$16 -> 1 | AE23: =(AD23/$AD$17)*100 -> 0 | AF23: =LOOKUP(AE23,{0,1,9,17,25,33,41,49,57,66,75,76,77,78,79,80,81,82,83,84,85,86,87,88,89,90,91,93,95,97,99},{"4.0","3.9","3.8","3.7","3.6","3.5","3.4","3.3","3.2","3.1","3.0","2.9","2.8","2.7","2.6","2.5","2.4","2.3","2.2","2.1","2.0","1.9","1.8","1.7","1.6","1.5","1.4","1.3","1.2","1.1","1.0"}) -> 4.0 | AG23: =AF23*$AG$16 -> 1 | AH23: =AG23+AC23+Y23+O23 -> 4 | AI23: =(AH23*1)/2 -> 2 | AJ23: =PRELIM!AH23 -> 4 | AK23: =(AJ23)/2 -> 2 | AL23: =SUM(AK23+AI23) -> 4
A24: ='Class List'!A8 -> 6 | B24: ='Class List'!B8 -> 0 | C24: ='Class List'!C8 -> , | D24: ='Class List'!D8 -> 0 | E24: ='Class List'!E8 -> 0 | L24: =SUM(F24:K24) -> 0 | M24: =(L24/$L$17)*100 -> 0 | N24: =LOOKUP(M24,{0,1,9,17,25,33,41,49,57,66,75,76,77,78,79,80,81,82,83,84,85,86,87,88,89,90,91,93,95,97,99},{"4.0","3.9","3.8","3.7","3.6","3.5","3.4","3.3","3.2","3.1","3.0","2.9","2.8","2.7","2.6","2.5","2.4","2.3","2.2","2.1","2.0","1.9","1.8","1.7","1.6","1.5","1.4","1.3","1.2","1.1","1.0"}) -> 4.0 | O24: =N24*$O$16 -> 0.6 | V24: =SUM(P24:U24) -> 0 | W24: =(V24/$V$17)*100 -> 0 | X24: =LOOKUP(W24,{0,1,9,17,25,33,41,49,57,66,75,76,77,78,79,80,81,82,83,84,85,86,87,88,89,90,91,93,95,97,99},{"4.0","3.9","3.8","3.7","3.6","3.5","3.4","3.3","3.2","3.1","3.0","2.9","2.8","2.7","2.6","2.5","2.4","2.3","2.2","2.1","2.0","1.9","1.8","1.7","1.6","1.5","1.4","1.3","1.2","1.1","1.0"}) -> 4.0 | Y24: =X24*$Y$16 -> 1.4 | AA24: =(Z24/$Z$17)*100 -> 0 | AB24: =LOOKUP(AA24,{0,1,9,17,25,33,41,49,57,66,75,76,77,78,79,80,81,82,83,84,85,86,87,88,89,90,91,93,95,97,99},{"4.0","3.9","3.8","3.7","3.6","3.5","3.4","3.3","3.2","3.1","3.0","2.9","2.8","2.7","2.6","2.5","2.4","2.3","2.2","2.1","2.0","1.9","1.8","1.7","1.6","1.5","1.4","1.3","1.2","1.1","1.0"}) -> 4.0 | AC24: =AB24*$AC$16 -> 1 | AE24: =(AD24/$AD$17)*100 -> 0 | AF24: =LOOKUP(AE24,{0,1,9,17,25,33,41,49,57,66,75,76,77,78,79,80,81,82,83,84,85,86,87,88,89,90,91,93,95,97,99},{"4.0","3.9","3.8","3.7","3.6","3.5","3.4","3.3","3.2","3.1","3.0","2.9","2.8","2.7","2.6","2.5","2.4","2.3","2.2","2.1","2.0","1.9","1.8","1.7","1.6","1.5","1.4","1.3","1.2","1.1","1.0"}) -> 4.0 | AG24: =AF24*$AG$16 -> 1 | AH24: =AG24+AC24+Y24+O24 -> 4 | AI24: =(AH24*1)/2 -> 2 | AJ24: =PRELIM!AH24 -> 4 | AK24: =(AJ24)/2 -> 2 | AL24: =SUM(AK24+AI24) -> 4
A25: ='Class List'!A9 -> 7 | B25: ='Class List'!B9 -> 0 | C25: ='Class List'!C9 -> , | D25: ='Class List'!D9 -> 0 | E25: ='Class List'!E9 -> 0 | L25: =SUM(F25:K25) -> 0 | M25: =(L25/$L$17)*100 -> 0 | N25: =LOOKUP(M25,{0,1,9,17,25,33,41,49,57,66,75,76,77,78,79,80,81,82,83,84,85,86,87,88,89,90,91,93,95,97,99},{"4.0","3.9","3.8","3.7","3.6","3.5","3.4","3.3","3.2","3.1","3.0","2.9","2.8","2.7","2.6","2.5","2.4","2.3","2.2","2.1","2.0","1.9","1.8","1.7","1.6","1.5","1.4","1.3","1.2","1.1","1.0"}) -> 4.0 | O25: =N25*$O$16 -> 0.6 | V25: =SUM(P25:U25) -> 0 | W25: =(V25/$V$17)*100 -> 0 | X25: =LOOKUP(W25,{0,1,9,17,25,33,41,49,57,66,75,76,77,78,79,80,81,82,83,84,85,86,87,88,89,90,91,93,95,97,99},{"4.0","3.9","3.8","3.7","3.6","3.5","3.4","3.3","3.2","3.1","3.0","2.9","2.8","2.7","2.6","2.5","2.4","2.3","2.2","2.1","2.0","1.9","1.8","1.7","1.6","1.5","1.4","1.3","1.2","1.1","1.0"}) -> 4.0 | Y25: =X25*$Y$16 -> 1.4 | AA25: =(Z25/$Z$17)*100 -> 0 | AB25: =LOOKUP(AA25,{0,1,9,17,25,33,41,49,57,66,75,76,77,78,79,80,81,82,83,84,85,86,87,88,89,90,91,93,95,97,99},{"4.0","3.9","3.8","3.7","3.6","3.5","3.4","3.3","3.2","3.1","3.0","2.9","2.8","2.7","2.6","2.5","2.4","2.3","2.2","2.1","2.0","1.9","1.8","1.7","1.6","1.5","1.4","1.3","1.2","1.1","1.0"}) -> 4.0 | AC25: =AB25*$AC$16 -> 1 | AE25: =(AD25/$AD$17)*100 -> 0 | AF25: =LOOKUP(AE25,{0,1,9,17,25,33,41,49,57,66,75,76,77,78,79,80,81,82,83,84,85,86,87,88,89,90,91,93,95,97,99},{"4.0","3.9","3.8","3.7","3.6","3.5","3.4","3.3","3.2","3.1","3.0","2.9","2.8","2.7","2.6","2.5","2.4","2.3","2.2","2.1","2.0","1.9","1.8","1.7","1.6","1.5","1.4","1.3","1.2","1.1","1.0"}) -> 4.0 | AG25: =AF25*$AG$16 -> 1 | AH25: =AG25+AC25+Y25+O25 -> 4 | AI25: =(AH25*1)/2 -> 2 | AJ25: =PRELIM!AH25 -> 4 | AK25: =(AJ25)/2 -> 2 | AL25: =SUM(AK25+AI25) -> 4
A26: ='Class List'!A10 -> 8 | B26: ='Class List'!B10 -> 0 | C26: ='Class List'!C10 -> , | D26: ='Class List'!D10 -> 0 | E26: ='Class List'!E10 -> 0 | L26: =SUM(F26:K26) -> 0 | M26: =(L26/$L$17)*100 -> 0 | N26: =LOOKUP(M26,{0,1,9,17,25,33,41,49,57,66,75,76,77,78,79,80,81,82,83,84,85,86,87,88,89,90,91,93,95,97,99},{"4.0","3.9","3.8","3.7","3.6","3.5","3.4","3.3","3.2","3.1","3.0","2.9","2.8","2.7","2.6","2.5","2.4","2.3","2.2","2.1","2.0","1.9","1.8","1.7","1.6","1.5","1.4","1.3","1.2","1.1","1.0"}) -> 4.0 | O26: =N26*$O$16 -> 0.6 | V26: =SUM(P26:U26) -> 0 | W26: =(V26/$V$17)*100 -> 0 | X26: =LOOKUP(W26,{0,1,9,17,25,33,41,49,57,66,75,76,77,78,79,80,81,82,83,84,85,86,87,88,89,90,91,93,95,97,99},{"4.0","3.9","3.8","3.7","3.6","3.5","3.4","3.3","3.2","3.1","3.0","2.9","2.8","2.7","2.6","2.5","2.4","2.3","2.2","2.1","2.0","1.9","1.8","1.7","1.6","1.5","1.4","1.3","1.2","1.1","1.0"}) -> 4.0 | Y26: =X26*$Y$16 -> 1.4 | AA26: =(Z26/$Z$17)*100 -> 0 | AB26: =LOOKUP(AA26,{0,1,9,17,25,33,41,49,57,66,75,76,77,78,79,80,81,82,83,84,85,86,87,88,89,90,91,93,95,97,99},{"4.0","3.9","3.8","3.7","3.6","3.5","3.4","3.3","3.2","3.1","3.0","2.9","2.8","2.7","2.6","2.5","2.4","2.3","2.2","2.1","2.0","1.9","1.8","1.7","1.6","1.5","1.4","1.3","1.2","1.1","1.0"}) -> 4.0 | AC26: =AB26*$AC$16 -> 1 | AE26: =(AD26/$AD$17)*100 -> 0 | AF26: =LOOKUP(AE26,{0,1,9,17,25,33,41,49,57,66,75,76,77,78,79,80,81,82,83,84,85,86,87,88,89,90,91,93,95,97,99},{"4.0","3.9","3.8","3.7","3.6","3.5","3.4","3.3","3.2","3.1","3.0","2.9","2.8","2.7","2.6","2.5","2.4","2.3","2.2","2.1","2.0","1.9","1.8","1.7","1.6","1.5","1.4","1.3","1.2","1.1","1.0"}) -> 4.0 | AG26: =AF26*$AG$16 -> 1 | AH26: =AG26+AC26+Y26+O26 -> 4 | AI26: =(AH26*1)/2 -> 2 | AJ26: =PRELIM!AH26 -> 4 | AK26: =(AJ26)/2 -> 2 | AL26: =SUM(AK26+AI26) -> 4
A27: ='Class List'!A11 -> 9 | B27: ='Class List'!B11 -> 0 | C27: ='Class List'!C11 -> , | D27: ='Class List'!D11 -> 0 | E27: ='Class List'!E11 -> 0 | L27: =SUM(F27:K27) -> 0 | M27: =(L27/$L$17)*100 -> 0 | N27: =LOOKUP(M27,{0,1,9,17,25,33,41,49,57,66,75,76,77,78,79,80,81,82,83,84,85,86,87,88,89,90,91,93,95,97,99},{"4.0","3.9","3.8","3.7","3.6","3.5","3.4","3.3","3.2","3.1","3.0","2.9","2.8","2.7","2.6","2.5","2.4","2.3","2.2","2.1","2.0","1.9","1.8","1.7","1.6","1.5","1.4","1.3","1.2","1.1","1.0"}) -> 4.0 | O27: =N27*$O$16 -> 0.6 | V27: =SUM(P27:U27) -> 0 | W27: =(V27/$V$17)*100 -> 0 | X27: =LOOKUP(W27,{0,1,9,17,25,33,41,49,57,66,75,76,77,78,79,80,81,82,83,84,85,86,87,88,89,90,91,93,95,97,99},{"4.0","3.9","3.8","3.7","3.6","3.5","3.4","3.3","3.2","3.1","3.0","2.9","2.8","2.7","2.6","2.5","2.4","2.3","2.2","2.1","2.0","1.9","1.8","1.7","1.6","1.5","1.4","1.3","1.2","1.1","1.0"}) -> 4.0 | Y27: =X27*$Y$16 -> 1.4 | AA27: =(Z27/$Z$17)*100 -> 0 | AB27: =LOOKUP(AA27,{0,1,9,17,25,33,41,49,57,66,75,76,77,78,79,80,81,82,83,84,85,86,87,88,89,90,91,93,95,97,99},{"4.0","3.9","3.8","3.7","3.6","3.5","3.4","3.3","3.2","3.1","3.0","2.9","2.8","2.7","2.6","2.5","2.4","2.3","2.2","2.1","2.0","1.9","1.8","1.7","1.6","1.5","1.4","1.3","1.2","1.1","1.0"}) -> 4.0 | AC27: =AB27*$AC$16 -> 1 | AE27: =(AD27/$AD$17)*100 -> 0 | AF27: =LOOKUP(AE27,{0,1,9,17,25,33,41,49,57,66,75,76,77,78,79,80,81,82,83,84,85,86,87,88,89,90,91,93,95,97,99},{"4.0","3.9","3.8","3.7","3.6","3.5","3.4","3.3","3.2","3.1","3.0","2.9","2.8","2.7","2.6","2.5","2.4","2.3","2.2","2.1","2.0","1.9","1.8","1.7","1.6","1.5","1.4","1.3","1.2","1.1","1.0"}) -> 4.0 | AG27: =AF27*$AG$16 -> 1 | AH27: =AG27+AC27+Y27+O27 -> 4 | AI27: =(AH27*1)/2 -> 2 | AJ27: =PRELIM!AH27 -> 4 | AK27: =(AJ27)/2 -> 2 | AL27: =SUM(AK27+AI27) -> 4
A28: ='Class List'!A12 -> 10 | B28: ='Class List'!B12 -> 0 | C28: ='Class List'!C12 -> , | D28: ='Class List'!D12 -> 0 | E28: ='Class List'!E12 -> 0 | L28: =SUM(F28:K28) -> 0 | M28: =(L28/$L$17)*100 -> 0 | N28: =LOOKUP(M28,{0,1,9,17,25,33,41,49,57,66,75,76,77,78,79,80,81,82,83,84,85,86,87,88,89,90,91,93,95,97,99},{"4.0","3.9","3.8","3.7","3.6","3.5","3.4","3.3","3.2","3.1","3.0","2.9","2.8","2.7","2.6","2.5","2.4","2.3","2.2","2.1","2.0","1.9","1.8","1.7","1.6","1.5","1.4","1.3","1.2","1.1","1.0"}) -> 4.0 | O28: =N28*$O$16 -> 0.6 | V28: =SUM(P28:U28) -> 0 | W28: =(V28/$V$17)*100 -> 0 | X28: =LOOKUP(W28,{0,1,9,17,25,33,41,49,57,66,75,76,77,78,79,80,81,82,83,84,85,86,87,88,89,90,91,93,95,97,99},{"4.0","3.9","3.8","3.7","3.6","3.5","3.4","3.3","3.2","3.1","3.0","2.9","2.8","2.7","2.6","2.5","2.4","2.3","2.2","2.1","2.0","1.9","1.8","1.7","1.6","1.5","1.4","1.3","1.2","1.1","1.0"}) -> 4.0 | Y28: =X28*$Y$16 -> 1.4 | AA28: =(Z28/$Z$17)*100 -> 0 | AB28: =LOOKUP(AA28,{0,1,9,17,25,33,41,49,57,66,75,76,77,78,79,80,81,82,83,84,85,86,87,88,89,90,91,93,95,97,99},{"4.0","3.9","3.8","3.7","3.6","3.5","3.4","3.3","3.2","3.1","3.0","2.9","2.8","2.7","2.6","2.5","2.4","2.3","2.2","2.1","2.0","1.9","1.8","1.7","1.6","1.5","1.4","1.3","1.2","1.1","1.0"}) -> 4.0 | AC28: =AB28*$AC$16 -> 1 | AE28: =(AD28/$AD$17)*100 -> 0 | AF28: =LOOKUP(AE28,{0,1,9,17,25,33,41,49,57,66,75,76,77,78,79,80,81,82,83,84,85,86,87,88,89,90,91,93,95,97,99},{"4.0","3.9","3.8","3.7","3.6","3.5","3.4","3.3","3.2","3.1","3.0","2.9","2.8","2.7","2.6","2.5","2.4","2.3","2.2","2.1","2.0","1.9","1.8","1.7","1.6","1.5","1.4","1.3","1.2","1.1","1.0"}) -> 4.0 | AG28: =AF28*$AG$16 -> 1 | AH28: =AG28+AC28+Y28+O28 -> 4 | AI28: =(AH28*1)/2 -> 2 | AJ28: =PRELIM!AH28 -> 4 | AK28: =(AJ28)/2 -> 2 | AL28: =SUM(AK28+AI28) -> 4
A29: ='Class List'!A13 -> 11 | B29: ='Class List'!B13 -> 0 | C29: ='Class List'!C13 -> , | D29: ='Class List'!D13 -> 0 | E29: ='Class List'!E13 -> 0 | L29: =SUM(F29:K29) -> 0 | M29: =(L29/$L$17)*100 -> 0 | N29: =LOOKUP(M29,{0,1,9,17,25,33,41,49,57,66,75,76,77,78,79,80,81,82,83,84,85,86,87,88,89,90,91,93,95,97,99},{"4.0","3.9","3.8","3.7","3.6","3.5","3.4","3.3","3.2","3.1","3.0","2.9","2.8","2.7","2.6","2.5","2.4","2.3","2.2","2.1","2.0","1.9","1.8","1.7","1.6","1.5","1.4","1.3","1.2","1.1","1.0"}) -> 4.0 | O29: =N29*$O$16 -> 0.6 | V29: =SUM(P29:U29) -> 0 | W29: =(V29/$V$17)*100 -> 0 | X29: =LOOKUP(W29,{0,1,9,17,25,33,41,49,57,66,75,76,77,78,79,80,81,82,83,84,85,86,87,88,89,90,91,93,95,97,99},{"4.0","3.9","3.8","3.7","3.6","3.5","3.4","3.3","3.2","3.1","3.0","2.9","2.8","2.7","2.6","2.5","2.4","2.3","2.2","2.1","2.0","1.9","1.8","1.7","1.6","1.5","1.4","1.3","1.2","1.1","1.0"}) -> 4.0 | Y29: =X29*$Y$16 -> 1.4 | AA29: =(Z29/$Z$17)*100 -> 0 | AB29: =LOOKUP(AA29,{0,1,9,17,25,33,41,49,57,66,75,76,77,78,79,80,81,82,83,84,85,86,87,88,89,90,91,93,95,97,99},{"4.0","3.9","3.8","3.7","3.6","3.5","3.4","3.3","3.2","3.1","3.0","2.9","2.8","2.7","2.6","2.5","2.4","2.3","2.2","2.1","2.0","1.9","1.8","1.7","1.6","1.5","1.4","1.3","1.2","1.1","1.0"}) -> 4.0 | AC29: =AB29*$AC$16 -> 1 | AE29: =(AD29/$AD$17)*100 -> 0 | AF29: =LOOKUP(AE29,{0,1,9,17,25,33,41,49,57,66,75,76,77,78,79,80,81,82,83,84,85,86,87,88,89,90,91,93,95,97,99},{"4.0","3.9","3.8","3.7","3.6","3.5","3.4","3.3","3.2","3.1","3.0","2.9","2.8","2.7","2.6","2.5","2.4","2.3","2.2","2.1","2.0","1.9","1.8","1.7","1.6","1.5","1.4","1.3","1.2","1.1","1.0"}) -> 4.0 | AG29: =AF29*$AG$16 -> 1 | AH29: =AG29+AC29+Y29+O29 -> 4 | AI29: =(AH29*1)/2 -> 2 | AJ29: =PRELIM!AH29 -> 4 | AK29: =(AJ29)/2 -> 2 | AL29: =SUM(AK29+AI29) -> 4
A30: ='Class List'!A14 -> 12 | B30: ='Class List'!B14 -> 0 | C30: ='Class List'!C14 -> , | D30: ='Class List'!D14 -> 0 | E30: ='Class List'!E14 -> 0 | L30: =SUM(F30:K30) -> 0 | M30: =(L30/$L$17)*100 -> 0 | N30: =LOOKUP(M30,{0,1,9,17,25,33,41,49,57,66,75,76,77,78,79,80,81,82,83,84,85,86,87,88,89,90,91,93,95,97,99},{"4.0","3.9","3.8","3.7","3.6","3.5","3.4","3.3","3.2","3.1","3.0","2.9","2.8","2.7","2.6","2.5","2.4","2.3","2.2","2.1","2.0","1.9","1.8","1.7","1.6","1.5","1.4","1.3","1.2","1.1","1.0"}) -> 4.0 | O30: =N30*$O$16 -> 0.6 | V30: =SUM(P30:U30) -> 0 | W30: =(V30/$V$17)*100 -> 0 | X30: =LOOKUP(W30,{0,1,9,17,25,33,41,49,57,66,75,76,77,78,79,80,81,82,83,84,85,86,87,88,89,90,91,93,95,97,99},{"4.0","3.9","3.8","3.7","3.6","3.5","3.4","3.3","3.2","3.1","3.0","2.9","2.8","2.7","2.6","2.5","2.4","2.3","2.2","2.1","2.0","1.9","1.8","1.7","1.6","1.5","1.4","1.3","1.2","1.1","1.0"}) -> 4.0 | Y30: =X30*$Y$16 -> 1.4 | AA30: =(Z30/$Z$17)*100 -> 0 | AB30: =LOOKUP(AA30,{0,1,9,17,25,33,41,49,57,66,75,76,77,78,79,80,81,82,83,84,85,86,87,88,89,90,91,93,95,97,99},{"4.0","3.9","3.8","3.7","3.6","3.5","3.4","3.3","3.2","3.1","3.0","2.9","2.8","2.7","2.6","2.5","2.4","2.3","2.2","2.1","2.0","1.9","1.8","1.7","1.6","1.5","1.4","1.3","1.2","1.1","1.0"}) -> 4.0 | AC30: =AB30*$AC$16 -> 1 | AE30: =(AD30/$AD$17)*100 -> 0 | AF30: =LOOKUP(AE30,{0,1,9,17,25,33,41,49,57,66,75,76,77,78,79,80,81,82,83,84,85,86,87,88,89,90,91,93,95,97,99},{"4.0","3.9","3.8","3.7","3.6","3.5","3.4","3.3","3.2","3.1","3.0","2.9","2.8","2.7","2.6","2.5","2.4","2.3","2.2","2.1","2.0","1.9","1.8","1.7","1.6","1.5","1.4","1.3","1.2","1.1","1.0"}) -> 4.0 | AG30: =AF30*$AG$16 -> 1 | AH30: =AG30+AC30+Y30+O30 -> 4 | AI30: =(AH30*1)/2 -> 2 | AJ30: =PRELIM!AH30 -> 4 | AK30: =(AJ30)/2 -> 2 | AL30: =SUM(AK30+AI30) -> 4
... A78: ='Class List'!A62 -> 60 | B78: ='Class List'!B62 -> 0 | C78: ='Class List'!C62 -> , | D78: ='Class List'!D62 -> 0 | E78: ='Class List'!E62 -> 0 | L78: =SUM(F78:K78) -> 0 | M78: =(L78/$L$17)*100 -> 0 | N78: =LOOKUP(M78,{0,1,9,17,25,33,41,49,57,66,75,76,77,78,79,80,81,82,83,84,85,86,87,88,89,90,91,93,95,97,99},{"4.0","3.9","3.8","3.7","3.6","3.5","3.4","3.3","3.2","3.1","3.0","2.9","2.8","2.7","2.6","2.5","2.4","2.3","2.2","2.1","2.0","1.9","1.8","1.7","1.6","1.5","1.4","1.3","1.2","1.1","1.0"}) -> 4.0 | O78: =N78*$O$16 -> 0.6 | V78: =SUM(P78:U78) -> 0 | W78: =(V78/$V$17)*100 -> 0 | X78: =LOOKUP(W78,{0,1,9,17,25,33,41,49,57,66,75,76,77,78,79,80,81,82,83,84,85,86,87,88,89,90,91,93,95,97,99},{"4.0","3.9","3.8","3.7","3.6","3.5","3.4","3.3","3.2","3.1","3.0","2.9","2.8","2.7","2.6","2.5","2.4","2.3","2.2","2.1","2.0","1.9","1.8","1.7","1.6","1.5","1.4","1.3","1.2","1.1","1.0"}) -> 4.0 | Y78: =X78*$Y$16 -> 1.4 | AA78: =(Z78/$Z$17)*100 -> 0 | AB78: =LOOKUP(AA78,{0,1,9,17,25,33,41,49,57,66,75,76,77,78,79,80,81,82,83,84,85,86,87,88,89,90,91,93,95,97,99},{"4.0","3.9","3.8","3.7","3.6","3.5","3.4","3.3","3.2","3.1","3.0","2.9","2.8","2.7","2.6","2.5","2.4","2.3","2.2","2.1","2.0","1.9","1.8","1.7","1.6","1.5","1.4","1.3","1.2","1.1","1.0"}) -> 4.0 | AC78: =AB78*$AC$16 -> 1 | AE78: =(AD78/$AD$17)*100 -> 0 | AF78: =LOOKUP(AE78,{0,1,9,17,25,33,41,49,57,66,75,76,77,78,79,80,81,82,83,84,85,86,87,88,89,90,91,93,95,97,99},{"4.0","3.9","3.8","3.7","3.6","3.5","3.4","3.3","3.2","3.1","3.0","2.9","2.8","2.7","2.6","2.5","2.4","2.3","2.2","2.1","2.0","1.9","1.8","1.7","1.6","1.5","1.4","1.3","1.2","1.1","1.0"}) -> 4.0 | AG78: =AF78*$AG$16 -> 1 | AH78: =AG78+AC78+Y78+O78 -> 4 | AI78: =(AH78*1)/2 -> 2 | AJ78: =PRELIM!AH78 -> 4 | AK78: =(AJ78)/2 -> 2 | AL78: =SUM(AK78+AI78) -> 4
B81: Prepared by: | K81: Checked by: | AE81: Noted by:
B83: ='Class List'!J8 -> MARL VINCENT L. LABITAD, MPA | K83: MARL VINCENT L. LABITAD, MPA | AE83: RICHEL N. BACALTOS, Ed.D
B84: Faculty | K84: Head, Department of Business Management & Entrepreneurship | AE84: College President

Sheet FINAL
A2: TALISAY CITY COLLEGE
A3: Poblacion, Talisay City, Cebu
A4: ='Class List'!J6 -> First Semester, A.Y. 2026 - 2027
A5: ='Class List'!J7 -> Department of Business Management & Entrepreneurship
A7: Instructor : | E7: ='Class List'!J8 -> MARL VINCENT L. LABITAD, MPA
A8: Course No: | E8: ='Class List'!J9 -> ABM 1
A9: Descriptive Title: | E9: ='Class List'!J10 -> ORGANZIATION AND MANAGEMENT
A10: Schedule: | E10: ='Class List'!J11 -> MONDAY (9:00-10:30 AM) & WED (7:30-9:00 AM)
A12: F I N A L
A14: NAME | F14: ATTENDANCE (15%) | P14: PARTICIPATION and OTHER COURSEWORK (35%) | Y14: MAJOR PERFORMANCE (25%) | AC14: MAJOR EXAM (25%) | AG14: INITIAL FINAL GRADE | AH14: 4/5 | AI14: MIDTERM GRADE | AJ14: 1/5 | AK14: FINAL GRADE | AL14: FNL_FINAL GRADE | AM14: REMARKS
F16: A1 | G16: A2 | H16: A3 | I16: A4 | J16: A5 | K16: A6 | L16: TO | M16: %EQ | N16: GE | O16: 0.15 | P16: CW1 | Q16: CW2 | R16: CW3 | S16: CW4 | T16: CW5 | U16: TO | V16: %EQ | W16: GE | X16: 0.35 | Y16: MP | Z16: %EQ | AA16: GE | AB16: 0.25 | AC16: ST | AD16: %EQ | AE16: GE | AF16: 0.25
A17: # | B17: FAMILY NAME | C17: , | D17: FIRST NAME | E17: M.I. | F17: 100 | L17: =SUM(F17:K17) -> 100 | M17: =(L17/$L$17)*100 -> 100 | N17: =LOOKUP(M17,{0,1,4,7,11,15,19,23,27,31,35,39,43,47,51,55,59,63,67,71,75,76,77,78,79,80,81,82,83,84,85,86,87,88,89,90,91,93,95,97,99},{"5.0","4.9","4.8","4.7","4.6","4.5","4.4","4.3","4.2","4.1","4.0","3.9","3.8","3.7","3.6","3.5","3.4","3.3","3.2","3.1","3.0","2.9","2.8","2.7","2.6","2.5","2.4","2.3","2.2","2.1","2.0","1.9","1.8","1.7","1.6","1.5","1.4","1.3","1.2","1.1","1.0"}) -> 1.0 | O17: =N17*$O$16 -> 0.15 | P17: 20 | U17: =SUM(P17:T17) -> 20 | V17: =(U17/$U$17)*100 -> 100 | W17: =LOOKUP(V17,{0,1,4,7,11,15,19,23,27,31,35,39,43,47,51,55,59,63,67,71,75,76,77,78,79,80,81,82,83,84,85,86,87,88,89,90,91,93,95,97,99},{"5.0","4.9","4.8","4.7","4.6","4.5","4.4","4.3","4.2","4.1","4.0","3.9","3.8","3.7","3.6","3.5","3.4","3.3","3.2","3.1","3.0","2.9","2.8","2.7","2.6","2.5","2.4","2.3","2.2","2.1","2.0","1.9","1.8","1.7","1.6","1.5","1.4","1.3","1.2","1.1","1.0"}) -> 1.0 | X17: =W17*$X$16 -> 0.35 | Y17: 100 | Z17: =(Y17/$Y$17)*100 -> 100 | AA17: =LOOKUP(Z17,{0,1,4,7,11,15,19,23,27,31,35,39,43,47,51,55,59,63,67,71,75,76,77,78,79,80,81,82,83,84,85,86,87,88,89,90,91,93,95,97,99},{"5.0","4.9","4.8","4.7","4.6","4.5","4.4","4.3","4.2","4.1","4.0","3.9","3.8","3.7","3.6","3.5","3.4","3.3","3.2","3.1","3.0","2.9","2.8","2.7","2.6","2.5","2.4","2.3","2.2","2.1","2.0","1.9","1.8","1.7","1.6","1.5","1.4","1.3","1.2","1.1","1.0"}) -> 1.0 | AB17: =AA17*$AB$16 -> 0.25 | AC17: 100 | AD17: =(AC17/$AC$17)*100 -> 100 | AE17: =LOOKUP(AD17,{0,1,4,7,11,15,19,23,27,31,35,39,43,47,51,55,59,63,67,71,75,76,77,78,79,80,81,82,83,84,85,86,87,88,89,90,91,93,95,97,99},{"5.0","4.9","4.8","4.7","4.6","4.5","4.4","4.3","4.2","4.1","4.0","3.9","3.8","3.7","3.6","3.5","3.4","3.3","3.2","3.1","3.0","2.9","2.8","2.7","2.6","2.5","2.4","2.3","2.2","2.1","2.0","1.9","1.8","1.7","1.6","1.5","1.4","1.3","1.2","1.1","1.0"}) -> 1.0 | AF17: =AE17*$AF$16 -> 0.25 | AG17: =AF17+AB17+X17+O17 -> 1 | AH17: =(AG17*4)/5 -> 0.8 | AI17: =MIDTERM!AL17 -> 1 | AJ17: =(AI17)/5 -> 0.2 | AK17: =SUM(AJ17+AH17) -> 1 | AL17: =IF(AK17>3,5,IF(AK17>3,3,IF(AK17>=1,AK17))) -> 1 | AM17: =IF(AL17>3.5,"FAILED",IF(AL17>3,3,IF(AL17>=1,"PASSED",IF(AL17="","NO CREDIT")))) -> PASSED
